Workbook

Sheet Executive Summary
A1: AI Prior Authorization Platform — Market Opportunity Summary
A2: US + Canada Healthcare — TAM / SAM / SOM (US$, unless noted). All figures link live to the underlying model.
B4: Geography | C4: Software TAM ($B) | D4: SAM ($B) | E4: SOM — Base ($B) | F4: SOM — Upside ($B)
B5: United States | C5: ='US National Model'!C13 -> 12.96 | D5: ='US National Model'!C16 -> 5.184 | E5: ='US National Model'!C19 -> 0.07776 | F5: ='US National Model'!C21 -> 0.15552
B6: Canada | C6: ='Canada National Model'!D13 -> 0.44318592 | D6: ='Canada National Model'!D16 -> 0.17727437 | E6: ='Canada National Model'!D19 -> 0.0026591155 | F6: ='Canada National Model'!D21 -> 0.005318231
B7: US + CANADA COMBINED | C7: =SUM(C5:C6) -> 13.403186 | D7: =SUM(D5:D6) -> 5.3612744 | E7: =SUM(E5:E6) -> 0.080419116 | F7: =SUM(F5:F6) -> 0.16083823
B10: Top 10 US states by opportunity (base-case SOM)
B11: State | C11: TAM ($M) | D11: SAM ($M) | E11: SOM — Base ($M) | F11: SOM — Upside ($M)
B12: California | C12: {=INDEX('US State Breakdown'!$G$5:$G$55,MATCH($B12,'US State Breakdown'!$B$5:$B$55,0))} -> 1578.1651 | D12: {=INDEX('US State Breakdown'!$H$5:$H$55,MATCH($B12,'US State Breakdown'!$B$5:$B$55,0))} -> 631.26605 | E12: {=INDEX('US State Breakdown'!$I$5:$I$55,MATCH($B12,'US State Breakdown'!$B$5:$B$55,0))} -> 9.4689908 | F12: {=INDEX('US State Breakdown'!$J$5:$J$55,MATCH($B12,'US State Breakdown'!$B$5:$B$55,0))} -> 18.937982
B13: Texas | C13: {=INDEX('US State Breakdown'!$G$5:$G$55,MATCH($B13,'US State Breakdown'!$B$5:$B$55,0))} -> 1085.6389 | D13: {=INDEX('US State Breakdown'!$H$5:$H$55,MATCH($B13,'US State Breakdown'!$B$5:$B$55,0))} -> 434.25555 | E13: {=INDEX('US State Breakdown'!$I$5:$I$55,MATCH($B13,'US State Breakdown'!$B$5:$B$55,0))} -> 6.5138332 | F13: {=INDEX('US State Breakdown'!$J$5:$J$55,MATCH($B13,'US State Breakdown'!$B$5:$B$55,0))} -> 13.027666
B14: New York | C14: {=INDEX('US State Breakdown'!$G$5:$G$55,MATCH($B14,'US State Breakdown'!$B$5:$B$55,0))} -> 935.64574 | D14: {=INDEX('US State Breakdown'!$H$5:$H$55,MATCH($B14,'US State Breakdown'!$B$5:$B$55,0))} -> 374.2583 | E14: {=INDEX('US State Breakdown'!$I$5:$I$55,MATCH($B14,'US State Breakdown'!$B$5:$B$55,0))} -> 5.6138745 | F14: {=INDEX('US State Breakdown'!$J$5:$J$55,MATCH($B14,'US State Breakdown'!$B$5:$B$55,0))} -> 11.227749
B15: Florida | C15: {=INDEX('US State Breakdown'!$G$5:$G$55,MATCH($B15,'US State Breakdown'!$B$5:$B$55,0))} -> 919.84482 | D15: {=INDEX('US State Breakdown'!$H$5:$H$55,MATCH($B15,'US State Breakdown'!$B$5:$B$55,0))} -> 367.93793 | E15: {=INDEX('US State Breakdown'!$I$5:$I$55,MATCH($B15,'US State Breakdown'!$B$5:$B$55,0))} -> 5.5190689 | F15: {=INDEX('US State Breakdown'!$J$5:$J$55,MATCH($B15,'US State Breakdown'!$B$5:$B$55,0))} -> 11.038138
B16: Pennsylvania | C16: {=INDEX('US State Breakdown'!$G$5:$G$55,MATCH($B16,'US State Breakdown'!$B$5:$B$55,0))} -> 530.10162 | D16: {=INDEX('US State Breakdown'!$H$5:$H$55,MATCH($B16,'US State Breakdown'!$B$5:$B$55,0))} -> 212.04065 | E16: {=INDEX('US State Breakdown'!$I$5:$I$55,MATCH($B16,'US State Breakdown'!$B$5:$B$55,0))} -> 3.1806097 | F16: {=INDEX('US State Breakdown'!$J$5:$J$55,MATCH($B16,'US State Breakdown'!$B$5:$B$55,0))} -> 6.3612195
B17: Illinois | C17: {=INDEX('US State Breakdown'!$G$5:$G$55,MATCH($B17,'US State Breakdown'!$B$5:$B$55,0))} -> 475.87749 | D17: {=INDEX('US State Breakdown'!$H$5:$H$55,MATCH($B17,'US State Breakdown'!$B$5:$B$55,0))} -> 190.35099 | E17: {=INDEX('US State Breakdown'!$I$5:$I$55,MATCH($B17,'US State Breakdown'!$B$5:$B$55,0))} -> 2.8552649 | F17: {=INDEX('US State Breakdown'!$J$5:$J$55,MATCH($B17,'US State Breakdown'!$B$5:$B$55,0))} -> 5.7105298
B18: Ohio | C18: {=INDEX('US State Breakdown'!$G$5:$G$55,MATCH($B18,'US State Breakdown'!$B$5:$B$55,0))} -> 458.61209 | D18: {=INDEX('US State Breakdown'!$H$5:$H$55,MATCH($B18,'US State Breakdown'!$B$5:$B$55,0))} -> 183.44484 | E18: {=INDEX('US State Breakdown'!$I$5:$I$55,MATCH($B18,'US State Breakdown'!$B$5:$B$55,0))} -> 2.7516725 | F18: {=INDEX('US State Breakdown'!$J$5:$J$55,MATCH($B18,'US State Breakdown'!$B$5:$B$55,0))} -> 5.5033451
B19: New Jersey | C19: {=INDEX('US State Breakdown'!$G$5:$G$55,MATCH($B19,'US State Breakdown'!$B$5:$B$55,0))} -> 402.73079 | D19: {=INDEX('US State Breakdown'!$H$5:$H$55,MATCH($B19,'US State Breakdown'!$B$5:$B$55,0))} -> 161.09231 | E19: {=INDEX('US State Breakdown'!$I$5:$I$55,MATCH($B19,'US State Breakdown'!$B$5:$B$55,0))} -> 2.4163847 | F19: {=INDEX('US State Breakdown'!$J$5:$J$55,MATCH($B19,'US State Breakdown'!$B$5:$B$55,0))} -> 4.8327694
B20: Michigan | C20: {=INDEX('US State Breakdown'!$G$5:$G$55,MATCH($B20,'US State Breakdown'!$B$5:$B$55,0))} -> 389.24219 | D20: {=INDEX('US State Breakdown'!$H$5:$H$55,MATCH($B20,'US State Breakdown'!$B$5:$B$55,0))} -> 155.69688 | E20: {=INDEX('US State Breakdown'!$I$5:$I$55,MATCH($B20,'US State Breakdown'!$B$5:$B$55,0))} -> 2.3354532 | F20: {=INDEX('US State Breakdown'!$J$5:$J$55,MATCH($B20,'US State Breakdown'!$B$5:$B$55,0))} -> 4.6709063
B21: North Carolina | C21: {=INDEX('US State Breakdown'!$G$5:$G$55,MATCH($B21,'US State Breakdown'!$B$5:$B$55,0))} -> 381.53443 | D21: {=INDEX('US State Breakdown'!$H$5:$H$55,MATCH($B21,'US State Breakdown'!$B$5:$B$55,0))} -> 152.61377 | E21: {=INDEX('US State Breakdown'!$I$5:$I$55,MATCH($B21,'US State Breakdown'!$B$5:$B$55,0))} -> 2.2892066 | F21: {=INDEX('US State Breakdown'!$J$5:$J$55,MATCH($B21,'US State Breakdown'!$B$5:$B$55,0))} -> 4.5784131
B24: Top 5 Canadian provinces by opportunity (base-case SOM)
B25: Province | C25: TAM (US$M) | D25: SAM (US$M) | E25: SOM — Base (US$M) | F25: SOM — Upside (US$M)
B26: Ontario | C26: {=INDEX('Canada Province Breakdown'!$G$5:$G$17,MATCH($B26,'Canada Province Breakdown'!$B$5:$B$17,0))} -> 165.15808 | D26: {=INDEX('Canada Province Breakdown'!$H$5:$H$17,MATCH($B26,'Canada Province Breakdown'!$B$5:$B$17,0))} -> 66.063232 | E26: {=INDEX('Canada Province Breakdown'!$I$5:$I$17,MATCH($B26,'Canada Province Breakdown'!$B$5:$B$17,0))} -> 0.99094848 | F26: {=INDEX('Canada Province Breakdown'!$J$5:$J$17,MATCH($B26,'Canada Province Breakdown'!$B$5:$B$17,0))} -> 1.981897
B27: Quebec | C27: {=INDEX('Canada Province Breakdown'!$G$5:$G$17,MATCH($B27,'Canada Province Breakdown'!$B$5:$B$17,0))} -> 97.928509 | D27: {=INDEX('Canada Province Breakdown'!$H$5:$H$17,MATCH($B27,'Canada Province Breakdown'!$B$5:$B$17,0))} -> 39.171404 | E27: {=INDEX('Canada Province Breakdown'!$I$5:$I$17,MATCH($B27,'Canada Province Breakdown'!$B$5:$B$17,0))} -> 0.58757105 | F27: {=INDEX('Canada Province Breakdown'!$J$5:$J$17,MATCH($B27,'Canada Province Breakdown'!$B$5:$B$17,0))} -> 1.1751421
B28: British Columbia | C28: {=INDEX('Canada Province Breakdown'!$G$5:$G$17,MATCH($B28,'Canada Province Breakdown'!$B$5:$B$17,0))} -> 61.617938 | D28: {=INDEX('Canada Province Breakdown'!$H$5:$H$17,MATCH($B28,'Canada Province Breakdown'!$B$5:$B$17,0))} -> 24.647175 | E28: {=INDEX('Canada Province Breakdown'!$I$5:$I$17,MATCH($B28,'Canada Province Breakdown'!$B$5:$B$17,0))} -> 0.36970763 | F28: {=INDEX('Canada Province Breakdown'!$J$5:$J$17,MATCH($B28,'Canada Province Breakdown'!$B$5:$B$17,0))} -> 0.73941526
B29: Alberta | C29: {=INDEX('Canada Province Breakdown'!$G$5:$G$17,MATCH($B29,'Canada Province Breakdown'!$B$5:$B$17,0))} -> 51.759068 | D29: {=INDEX('Canada Province Breakdown'!$H$5:$H$17,MATCH($B29,'Canada Province Breakdown'!$B$5:$B$17,0))} -> 20.703627 | E29: {=INDEX('Canada Province Breakdown'!$I$5:$I$17,MATCH($B29,'Canada Province Breakdown'!$B$5:$B$17,0))} -> 0.31055441 | F29: {=INDEX('Canada Province Breakdown'!$J$5:$J$17,MATCH($B29,'Canada Province Breakdown'!$B$5:$B$17,0))} -> 0.62110882
B30: Manitoba | C30: {=INDEX('Canada Province Breakdown'!$G$5:$G$17,MATCH($B30,'Canada Province Breakdown'!$B$5:$B$17,0))} -> 17.330045 | D30: {=INDEX('Canada Province Breakdown'!$H$5:$H$17,MATCH($B30,'Canada Province Breakdown'!$B$5:$B$17,0))} -> 6.932018 | E30: {=INDEX('Canada Province Breakdown'!$I$5:$I$17,MATCH($B30,'Canada Province Breakdown'!$B$5:$B$17,0))} -> 0.10398027 | F30: {=INDEX('Canada Province Breakdown'!$J$5:$J$17,MATCH($B30,'Canada Province Breakdown'!$B$5:$B$17,0))} -> 0.20796054
B33: Note: 'Software TAM' = realistic vendor-capturable technology spend, derived from the full prior-auth/UM administrative cost pool via a 12% software-capture assumption (see Methodology + Assumptions tabs). SOM reflects a 1.5% (base) to 3.0% (upside) share of SAM captured within a 3–5 year horizon, consistent with a focused new entrant competing against Cohere Health, Rhyme, Availity, Waystar, Myndshft, and XSOLIS.

Sheet License Pricing & Breakeven
A1: ClearAuth AI — License Pricing Tiers & Product Investment Break-Even
A2: Built from the client's own Onboarding Cost & ROI Model (uploaded PDF). All figures are live formulas — edit any yellow cell.
B4: SHARED ASSUMPTIONS (source: ClearAuth AI Onboarding Cost & ROI Model, client PDF)
B5: PA volume per physician, low (per month) | C5: 160
B6: PA volume per physician, high (per month) | C6: 175
B7: Manual administrative cost per PA, low ($) | C7: 20
B8: Manual administrative cost per PA, high ($) | C8: 30
B9: Automation handling-time reduction | C9: 0.75
B10: Conservative realization factor | C10: 0.5
B11: Onboarding labor rate ($/hour) | C11: 50
B12: Onboarding implementation contingency | C12: 0.15
B13: Electronic payer routes per practice (E) | C13: 3
B14: Payer portal routes per practice (B) | C14: 2
B15: License fee — % of conservative monthly savings captured | C15: 0.2
B16: PA-volume, manual-cost, automation-reduction, realization-factor, labor-rate, contingency, and route-count figures are taken directly from the client's uploaded Onboarding Cost & ROI Model. The license-fee capture rate (last row) is a new commercial assumption — this model prices the recurring subscription as a share of the monthly savings ClearAuth delivers, on top of the existing one-time onboarding fee.
B19: ITEM 1 — RECURRING LICENSE PRICING BY PRACTICE SIZE
B20: Practice Size (Physicians) | C20: Monthly PA Volume — Low | D20: Monthly PA Volume — High | E20: Monthly Manual Burden — Low | F20: Monthly Manual Burden — High | G20: Conservative Monthly Savings — Low | H20: Conservative Monthly Savings — High | I20: Recommended License Fee ($/mo) | J20: Per-Physician Rate ($/mo) | K20: One-Time Onboarding Price (ref.)
B21: 10 | C21: =$B21*$C$5 -> 1600 | D21: =$B21*$C$6 -> 1750 | E21: =C21*$C$7 -> 32000 | F21: =D21*$C$8 -> 52500 | G21: =E21*$C$9*$C$10 -> 12000 | H21: =F21*$C$9*$C$10 -> 19687.5 | I21: =AVERAGE(G21:H21)*$C$15 -> 3168.75 | J21: =I21/B21 -> 316.875 | K21: =(34+0.25*B21+3*$C$13+4*$C$14)*$C$11*(1+$C$12) -> 3076.25
B22: 25 | C22: =$B22*$C$5 -> 4000 | D22: =$B22*$C$6 -> 4375 | E22: =C22*$C$7 -> 80000 | F22: =D22*$C$8 -> 131250 | G22: =E22*$C$9*$C$10 -> 30000 | H22: =F22*$C$9*$C$10 -> 49218.75 | I22: =AVERAGE(G22:H22)*$C$15 -> 7921.875 | J22: =I22/B22 -> 316.875 | K22: =(34+0.25*B22+3*$C$13+4*$C$14)*$C$11*(1+$C$12) -> 3291.875
B23: 50 | C23: =$B23*$C$5 -> 8000 | D23: =$B23*$C$6 -> 8750 | E23: =C23*$C$7 -> 160000 | F23: =D23*$C$8 -> 262500 | G23: =E23*$C$9*$C$10 -> 60000 | H23: =F23*$C$9*$C$10 -> 98437.5 | I23: =AVERAGE(G23:H23)*$C$15 -> 15843.75 | J23: =I23/B23 -> 316.875 | K23: =(34+0.25*B23+3*$C$13+4*$C$14)*$C$11*(1+$C$12) -> 3651.25
B24: 100 | C24: =$B24*$C$5 -> 16000 | D24: =$B24*$C$6 -> 17500 | E24: =C24*$C$7 -> 320000 | F24: =D24*$C$8 -> 525000 | G24: =E24*$C$9*$C$10 -> 120000 | H24: =F24*$C$9*$C$10 -> 196875 | I24: =AVERAGE(G24:H24)*$C$15 -> 31687.5 | J24: =I24/B24 -> 316.875 | K24: =(34+0.25*B24+3*$C$13+4*$C$14)*$C$11*(1+$C$12) -> 4370
B25: License fee = 20% of the midpoint conservative monthly savings for that practice size (i.e., ClearAuth keeps ~20% of the value delivered as recurring subscription revenue; the client keeps ~80%). Per-physician rate lands at roughly the same $ figure across tiers because savings scale near-linearly with PA volume — this is what makes per-physician pricing viable rather than a flat per-practice fee. Onboarding price (one-time) reuses the exact formula from the client's own ROI model: H = 34 + 0.25P + 3E + 4B, Cost = H x $50/hr, Quoted = Cost x 1.15.
B29: ITEM 2 — PRODUCT BUILD INVESTMENT: BREAK-EVEN ANALYSIS
B30: One-time product build investment ($) | C30: 75000
B31: Fixed monthly cost — managed services + cloud ($/mo) | C31: 3000
B32: New customers per month — Conservative scenario | C32: 1
B33: New customers per month — Base scenario | C33: 2
B34: New customers per month — Aggressive scenario | C34: 3
B35: Customer profile assumed for all three scenarios below: the 'Standard 10-physician practice' from Item 1 above — one-time onboarding fee plus recurring license fee, both computed there. Each scenario differs only in how many new practices sign per month; no churn is modeled.
B38: Scenario | C38: New customers / mo | D38: Break-even month
B39: Conservative | C39: =$C$32 -> 1 | D39: =IF(J69<$C$30,">24 months",COUNTIF(J46:J69,"<"&$C$30)+1) -> 7
B40: Base | C40: =$C$33 -> 2 | D40: =IF(J97<$C$30,">24 months",COUNTIF(J74:J97,"<"&$C$30)+1) -> 4
B41: Aggressive | C41: =$C$34 -> 3 | D41: =IF(J125<$C$30,">24 months",COUNTIF(J102:J125,"<"&$C$30)+1) -> 3
B44: CONSERVATIVE SCENARIO — Conservative new customer(s)/month (detail)
B45: Month | C45: New Customers | D45: Cumulative Customers | E45: Onboarding Revenue | F45: Recurring License Revenue | G45: Total Revenue | H45: Fixed Opex (Mgd Svcs+Cloud) | I45: Net Cash Flow | J45: Cumulative Net Cash Flow
B46: 1 | C46: =$C$32 -> 1 | D46: =C46 -> 1 | E46: =C46*$K$21 -> 3076.25 | F46: =D46*$I$21 -> 3168.75 | G46: =E46+F46 -> 6245 | H46: =$C$31 -> 3000 | I46: =G46-H46 -> 3245 | J46: =I46 -> 3245
B47: 2 | C47: =$C$32 -> 1 | D47: =D46+C47 -> 2 | E47: =C47*$K$21 -> 3076.25 | F47: =D47*$I$21 -> 6337.5 | G47: =E47+F47 -> 9413.75 | H47: =$C$31 -> 3000 | I47: =G47-H47 -> 6413.75 | J47: =J46+I47 -> 9658.75
B48: 3 | C48: =$C$32 -> 1 | D48: =D47+C48 -> 3 | E48: =C48*$K$21 -> 3076.25 | F48: =D48*$I$21 -> 9506.25 | G48: =E48+F48 -> 12582.5 | H48: =$C$31 -> 3000 | I48: =G48-H48 -> 9582.5 | J48: =J47+I48 -> 19241.25
B49: 4 | C49: =$C$32 -> 1 | D49: =D48+C49 -> 4 | E49: =C49*$K$21 -> 3076.25 | F49: =D49*$I$21 -> 12675 | G49: =E49+F49 -> 15751.25 | H49: =$C$31 -> 3000 | I49: =G49-H49 -> 12751.25 | J49: =J48+I49 -> 31992.5
B50: 5 | C50: =$C$32 -> 1 | D50: =D49+C50 -> 5 | E50: =C50*$K$21 -> 3076.25 | F50: =D50*$I$21 -> 15843.75 | G50: =E50+F50 -> 18920 | H50: =$C$31 -> 3000 | I50: =G50-H50 -> 15920 | J50: =J49+I50 -> 47912.5
...

Sheet Methodology
A1: AI Prior Authorization Platform — Market Sizing
A2: Methodology, definitions, and sources — read this sheet first
A5: PRODUCT CONTEXT
B6: Product analyzed | C6: AI-powered prior authorization / utilization-management (UM) automation platform for healthcare providers and payers — comparable to ClearAuth AI (clearauthai.com).
B7: Geography | C7: United States (national + all 50 states + DC) and Canada (national + 10 provinces + 3 territories).
B8: Vertical | C8: Healthcare — hospitals & health systems, medical groups/specialty practices, ambulatory surgical centers, and payers (health plans) that run prior-authorization and utilization-review workflows.
A10: DEFINITIONS USED IN THIS MODEL
B11: TAM (Total Addressable Market) | C11: The total annual SOFTWARE/technology spend that a category-defining PA/UM automation platform could theoretically capture across all US + Canada payers and providers, if it owned 100% of the category.
B12: SAM (Serviceable Addressable Market) | C12: The slice of TAM that is realistically reachable given this product's go-to-market: mid-size to large hospitals/health systems, multi-site specialty groups, and payer UM departments, sold via direct/channel sales in English-language North American markets.
B13: SOM (Serviceable Obtainable Market) | C13: The realistic revenue a new entrant can capture within a 3–5 year horizon, given the existing competitive set (Cohere Health, Rhyme, Availity, Waystar, Myndshft, Banjo Health, XSOLIS, and EHR-native UM modules from Epic/Oracle Health).
A15: WHY A TWO-STAGE 'COST POOL → SOFTWARE TAM' MODEL
B16: The problem | C16: Prior authorization touches a very large pool of administrative COST (staff time, denials/appeals, delayed care) — but only a fraction of that cost converts into money that flows to a software vendor. A TAM built directly off total healthcare spend (e.g., "25% of $5T is administrative, therefore TAM = $1.3T") wildly overstates what a company can realistically sell into and will not withstand diligence.
B17: The fix | C17: This model first sizes the full PRIOR-AUTH/UM COST POOL top-down from national health expenditure (an easy number to defend), then applies a SOFTWARE-CAPTURE RATE — the share of that cost pool that historically converts into vendor license/subscription revenue in adjacent categories (RCM automation, claims automation, denial management SaaS) — to arrive at a Software TAM. SAM and SOM are then carved out of that Software TAM. Every conversion factor is an explicit, editable, labeled assumption on the Assumptions tab (yellow cells) — change any one and the whole model recalculates.
A19: SOURCES & GROUNDING (verify before client-facing use)
B20: US National Health Expenditure (NHE) | C20: CMS Office of the Actuary NHE Historical & Projections data. 2023 actual NHE was ~$4.87 trillion; this model projects 2025 at ~$5.4T using CMS's published ~7%/yr near-term trend growth rate. CONFIRM the latest published NHE figure at cms.gov before presenting.
B21: Canada National Health Expenditure | C21: Canadian Institute for Health Information (CIHI), National Health Expenditure Trends. 2024 estimate used here is CAD $372B. CONFIRM latest figure at cihi.ca.
B22: Administrative cost share of spend | C22: Widely-cited academic/health-policy estimates (e.g., Health Affairs, JAMA, NEJM Catalyst research on billing & insurance-related costs) place US administrative overhead at 15–30% of total health spend; this model uses 25% as a defensible mid/upper estimate reflecting the US's payer-fragmented system. Canada's single-payer provincial system is typically cited as materially lower (~15–18%); this model uses 17%.
B23: Prior-auth/UM share of admin cost | C23: CAQH CORE Index research tracks prior authorization as one of the costliest per-transaction administrative categories (alongside claims and eligibility). This model assumes PA/UM activities represent ~8% of total administrative cost — a placeholder assumption that should be refined against the latest CAQH Index report (caqh.org/core/index) before external use.
B24: Software-capture rate | C24: SaaS vendors in adjacent healthcare-admin-automation categories (denials management, RCM automation) typically price on value delivered, capturing roughly 10–15% of the underlying manual-cost pool as license/subscription fees. This model uses 12%.
B25: State/province apportionment | C25: US state weights = 2024 Census population estimate × a directional per-capita health-spending index (reflecting known patterns, e.g., higher per-capita spend in MA/NY/AK/DC, lower in UT/ID/NV). Canada province weights use 2024 population estimates with a smaller remoteness-cost adjustment for the territories. BOTH should be re-based on CMS's State Health Expenditure Accounts (cms.gov) and CIHI provincial data for a final client deliverable — the values here are directional, not official state-level statistics.
A27: HOW TO USE THIS WORKBOOK
B28: 1. | C28: Start on 'Assumptions' — every yellow cell is an editable lever. Change any of them (e.g., a more conservative software-capture rate) and every other tab recalculates automatically.
B29: 2. | C29: 'US National Model' and 'Canada National Model' show the full waterfall from national health spend down to TAM / SAM / SOM.
B30: 3. | C30: 'US State Breakdown' and 'Canada Province Breakdown' split those national totals across all states/provinces.
B31: 4. | C31: 'Executive Summary' is the one-page rollup — this is the tab to screenshot or present.
C33: This model was built without live web access in this session, so every dollar figure is drawn from general industry knowledge current to Jan 2026, not a fresh pull of the latest published reports. Before presenting to the client, re-verify: (a) the latest CMS NHE topline figure, (b) the latest CAQH CORE Index prior-auth statistics, and (c) any named-vendor market-share claims. Treat the numbers here as a rigorous, transparent MODEL — not as a quoted market-research figure.

Sheet Assumptions
A1: Key Assumptions
A2: Edit any yellow cell — every other tab recalculates from these inputs
B4: Assumption | C4: Value | D4: Note / Source
B5: US National Health Expenditure, 2025E ($B) | C5: 5400 | D5: CMS NHE Historical & Projections; 2023 actual $4,867B, projected fwd at ~7%/yr trend. VERIFY latest CMS figure.
B6: Canada National Health Expenditure, 2024E (CAD $B) | C6: 372 | D6: CIHI National Health Expenditure Trends. VERIFY latest CIHI figure.
B7: CAD → USD exchange rate | C7: 0.73 | D7: Illustrative FX rate — update to spot rate before presenting.
B8: US administrative cost, % of NHE | C8: 0.25 | D8: Health-policy literature range 15–30%; fragmented multi-payer system skews toward the higher end.
B9: Canada administrative cost, % of NHE | C9: 0.17 | D9: Single-payer provincial systems typically cited lower than the US.
B10: Prior-auth / UM share of administrative cost | C10: 0.08 | D10: Placeholder — refine against CAQH CORE Index prior-authorization cost data.
B11: Software-capture rate (cost pool → vendor software TAM) | C11: 0.12 | D11: Typical SaaS value-capture in adjacent RCM/denials-automation categories (~10–15%).
B12: SAM as % of Software TAM (reachable segment) | C12: 0.4 | D12: Reflects focus on hospitals/health systems + specialty groups + payer UM depts, direct/channel sales, NA English-language markets.
B13: SOM as % of SAM (3–5 year realistic capture) | C13: 0.015 | D13: Reasonable new-entrant share in a category with established players (Cohere Health, Rhyme, Availity, Waystar, Myndshft, XSOLIS).
B14: Optimistic SOM as % of SAM (upside case) | C14: 0.03 | D14: Upside case if the product wins a clear wedge (e.g., a specialty vertical or a flagship health-system logo) and expands faster.

Sheet US National Model
A1: United States — National TAM / SAM / SOM Waterfall
A2: All figures in USD $ billions unless noted. Formulas link to Assumptions tab.
B4: Line item | C4: $ Billions | D4: Formula logic
B5: 1. US National Health Expenditure (NHE) | C5: =Assumptions!$C$5 -> 5400 | D5: Total US healthcare spend, all payers, 2025E.
B6: 2. Administrative cost % of NHE | C6: =Assumptions!$C$8 -> 0.25 | D6: Billing, insurance-related, and utilization administration.
B7: 3. Total US healthcare administrative spend | C7: =C5*C6 -> 1350 | D7: Row 1 x Row 2.
B9: 4. Prior-auth / UM share of administrative cost | C9: =Assumptions!$C$10 -> 0.08 | D9: Placeholder — refine vs. CAQH CORE Index.
B10: 5. US Prior-Auth / UM COST POOL ('Problem TAM') | C10: =C7*C9 -> 108 | D10: Total cost currently spent (staff time + payer UM ops + denials/appeals) on PA/UM — NOT a software number.
B12: 6. Software-capture rate | C12: =Assumptions!$C$11 -> 0.12 | D12: Share of the cost pool that converts to vendor SaaS/license revenue.
B13: 7. US SOFTWARE TAM | C13: =C10*C12 -> 12.96 | D13: Row 5 x Row 6 — the realistic total software/tech spend category.
B15: 8. SAM as % of Software TAM | C15: =Assumptions!$C$12 -> 0.4 | D15: Reachable segment: hospitals/health systems, specialty groups, payer UM depts.
B16: 9. US SAM (Serviceable Addressable Market) | C16: =C13*C15 -> 5.184 | D16: Row 7 x Row 8.
B18: 10. Base-case SOM as % of SAM (3–5 yr) | C18: =Assumptions!$C$13 -> 0.015 | D18: Realistic new-entrant capture vs. established competitors.
B19: 11. US SOM — Base case | C19: =C16*C18 -> 0.07776 | D19: Row 9 x Row 10. Realistic 3-5yr revenue opportunity.
B20: 12. Optimistic SOM as % of SAM (upside) | C20: =Assumptions!$C$14 -> 0.03 | D20: Upside case with a strong wedge / flagship logo.
B21: 13. US SOM — Upside case | C21: =C16*C20 -> 0.15552 | D21: Row 9 x Row 12.

Sheet US State Breakdown
A1: United States — State-by-State TAM / SAM / SOM
A2: Apportioned from the US National Model using population share x a directional per-capita health-spend index. VERIFY against CMS State Health Expenditure Accounts before external use.
B4: State | C4: 2024E Population (M) | D4: Pop. Share | E4: Per-Capita Spend Index | F4: Weighted Share | G4: TAM ($M) | H4: SAM ($M) | I4: SOM — Base ($M) | J4: SOM — Upside ($M)
B5: California | C5: 39 | D5: =C5/SUM($C$5:$C$55) -> 0.11509517 | E5: 1.05 | F5: =D5*E5 -> 0.12084993 | G5: =($F5/$F$57)*'US National Model'!$C$13*1000 -> 1578.1651 | H5: =($F5/$F$57)*'US National Model'!$C$16*1000 -> 631.26605 | I5: =($F5/$F$57)*'US National Model'!$C$19*1000 -> 9.4689908 | J5: =($F5/$F$57)*'US National Model'!$C$21*1000 -> 18.937982
B6: Texas | C6: 31.3 | D6: =C6/SUM($C$5:$C$55) -> 0.092371256 | E6: 0.9 | F6: =D6*E6 -> 0.08313413 | G6: =($F6/$F$57)*'US National Model'!$C$13*1000 -> 1085.6389 | H6: =($F6/$F$57)*'US National Model'!$C$16*1000 -> 434.25555 | I6: =($F6/$F$57)*'US National Model'!$C$19*1000 -> 6.5138332 | J6: =($F6/$F$57)*'US National Model'!$C$21*1000 -> 13.027666
B7: Florida | C7: 23.4 | D7: =C7/SUM($C$5:$C$55) -> 0.069057105 | E7: 1.02 | F7: =D7*E7 -> 0.070438247 | G7: =($F7/$F$57)*'US National Model'!$C$13*1000 -> 919.84482 | H7: =($F7/$F$57)*'US National Model'!$C$16*1000 -> 367.93793 | I7: =($F7/$F$57)*'US National Model'!$C$19*1000 -> 5.5190689 | J7: =($F7/$F$57)*'US National Model'!$C$21*1000 -> 11.038138
B8: New York | C8: 19.9 | D8: =C8/SUM($C$5:$C$55) -> 0.058728051 | E8: 1.22 | F8: =D8*E8 -> 0.071648222 | G8: =($F8/$F$57)*'US National Model'!$C$13*1000 -> 935.64574 | H8: =($F8/$F$57)*'US National Model'!$C$16*1000 -> 374.2583 | I8: =($F8/$F$57)*'US National Model'!$C$19*1000 -> 5.6138745 | J8: =($F8/$F$57)*'US National Model'!$C$21*1000 -> 11.227749
B9: Pennsylvania | C9: 13.1 | D9: =C9/SUM($C$5:$C$55) -> 0.038660174 | E9: 1.05 | F9: =D9*E9 -> 0.040593183 | G9: =($F9/$F$57)*'US National Model'!$C$13*1000 -> 530.10162 | H9: =($F9/$F$57)*'US National Model'!$C$16*1000 -> 212.04065 | I9: =($F9/$F$57)*'US National Model'!$C$19*1000 -> 3.1806097 | J9: =($F9/$F$57)*'US National Model'!$C$21*1000 -> 6.3612195
B10: Illinois | C10: 12.6 | D10: =C10/SUM($C$5:$C$55) -> 0.037184595 | E10: 0.98 | F10: =D10*E10 -> 0.036440903 | G10: =($F10/$F$57)*'US National Model'!$C$13*1000 -> 475.87749 | H10: =($F10/$F$57)*'US National Model'!$C$16*1000 -> 190.35099 | I10: =($F10/$F$57)*'US National Model'!$C$19*1000 -> 2.8552649 | J10: =($F10/$F$57)*'US National Model'!$C$21*1000 -> 5.7105298
B11: Ohio | C11: 11.9 | D11: =C11/SUM($C$5:$C$55) -> 0.035118784 | E11: 1 | F11: =D11*E11 -> 0.035118784 | G11: =($F11/$F$57)*'US National Model'!$C$13*1000 -> 458.61209 | H11: =($F11/$F$57)*'US National Model'!$C$16*1000 -> 183.44484 | I11: =($F11/$F$57)*'US National Model'!$C$19*1000 -> 2.7516725 | J11: =($F11/$F$57)*'US National Model'!$C$21*1000 -> 5.5033451
B12: Georgia | C12: 11.2 | D12: =C12/SUM($C$5:$C$55) -> 0.033052973 | E12: 0.82 | F12: =D12*E12 -> 0.027103438 | G12: =($F12/$F$57)*'US National Model'!$C$13*1000 -> 353.94063 | H12: =($F12/$F$57)*'US National Model'!$C$16*1000 -> 141.57625 | I12: =($F12/$F$57)*'US National Model'!$C$19*1000 -> 2.1236438 | J12: =($F12/$F$57)*'US National Model'!$C$21*1000 -> 4.2472875
B13: North Carolina | C13: 11 | D13: =C13/SUM($C$5:$C$55) -> 0.032462742 | E13: 0.9 | F13: =D13*E13 -> 0.029216467 | G13: =($F13/$F$57)*'US National Model'!$C$13*1000 -> 381.53443 | H13: =($F13/$F$57)*'US National Model'!$C$16*1000 -> 152.61377 | I13: =($F13/$F$57)*'US National Model'!$C$19*1000 -> 2.2892066 | J13: =($F13/$F$57)*'US National Model'!$C$21*1000 -> 4.5784131
B14: Michigan | C14: 10.1 | D14: =C14/SUM($C$5:$C$55) -> 0.029806699 | E14: 1 | F14: =D14*E14 -> 0.029806699 | G14: =($F14/$F$57)*'US National Model'!$C$13*1000 -> 389.24219 | H14: =($F14/$F$57)*'US National Model'!$C$16*1000 -> 155.69688 | I14: =($F14/$F$57)*'US National Model'!$C$19*1000 -> 2.3354532 | J14: =($F14/$F$57)*'US National Model'!$C$21*1000 -> 4.6709063
B15: New Jersey | C15: 9.5 | D15: =C15/SUM($C$5:$C$55) -> 0.028036004 | E15: 1.1 | F15: =D15*E15 -> 0.030839605 | G15: =($F15/$F$57)*'US National Model'!$C$13*1000 -> 402.73079 | H15: =($F15/$F$57)*'US National Model'!$C$16*1000 -> 161.09231 | I15: =($F15/$F$57)*'US National Model'!$C$19*1000 -> 2.4163847 | J15: =($F15/$F$57)*'US National Model'!$C$21*1000 -> 4.8327694
B16: Virginia | C16: 8.8 | D16: =C16/SUM($C$5:$C$55) -> 0.025970193 | E16: 0.92 | F16: =D16*E16 -> 0.023892578 | G16: =($F16/$F$57)*'US National Model'!$C$13*1000 -> 312.01038 | H16: =($F16/$F$57)*'US National Model'!$C$16*1000 -> 124.80415 | I16: =($F16/$F$57)*'US National Model'!$C$19*1000 -> 1.8720623 | J16: =($F16/$F$57)*'US National Model'!$C$21*1000 -> 3.7441245
... B55: District of Columbia | C55: 0.68 | D55: =C55/SUM($C$5:$C$55) -> 0.0020067877 | E55: 1.9 | F55: =D55*E55 -> 0.0038128966 | G55: =($F55/$F$57)*'US National Model'!$C$13*1000 -> 49.79217 | H55: =($F55/$F$57)*'US National Model'!$C$16*1000 -> 19.916868 | I55: =($F55/$F$57)*'US National Model'!$C$19*1000 -> 0.29875302 | J55: =($F55/$F$57)*'US National Model'!$C$21*1000 -> 0.59750604
B57: TOTAL (sum of weighted shares — used to normalize) | F57: =SUM(F5:F55) -> 0.99242792
B58: US TOTAL (all 50 states + DC) | G58: =SUM(G5:G55) -> 12960 | H58: =SUM(H5:H55) -> 5184 | I58: =SUM(I5:I55) -> 77.76 | J58: =SUM(J5:J55) -> 155.52

Sheet Canada National Model
A1: Canada — National TAM / SAM / SOM Waterfall
A2: Figures shown in CAD and USD billions. Formulas link to Assumptions tab.
B4: Line item | C4: CAD $B | D4: USD $B | E4: Formula logic
B5: 1. Canada National Health Expenditure (NHE) | C5: =Assumptions!$C$6 -> 372 | D5: =C5*Assumptions!$C$7 -> 271.56 | E5: Total Canada healthcare spend, all payers/provinces, 2024E.
B6: 2. Administrative cost % of NHE | C6: =Assumptions!$C$9 -> 0.17 | D6: =C6 -> 0.17 | E6: Lower than US — single-payer provincial systems.
B7: 3. Total Canada healthcare administrative spend | C7: =C5*C6 -> 63.24 | D7: =D5*D6 -> 46.1652 | E7: Row 1 x Row 2.
B9: 4. Prior-auth / UM share of administrative cost | C9: =Assumptions!$C$10 -> 0.08 | D9: =C9 -> 0.08 | E9: Same placeholder share as US model.
B10: 5. Canada Prior-Auth / UM COST POOL ('Problem TAM') | C10: =C7*C9 -> 5.0592 | D10: =D7*D9 -> 3.693216 | E10: Total cost currently spent on PA/UM across Canada — not a software number.
B12: 6. Software-capture rate | C12: =Assumptions!$C$11 -> 0.12 | D12: =C12 -> 0.12 | E12: Same capture-rate assumption as US model.
B13: 7. Canada SOFTWARE TAM | C13: =C10*C12 -> 0.607104 | D13: =D10*D12 -> 0.44318592 | E13: Row 5 x Row 6.
B15: 8. SAM as % of Software TAM | C15: =Assumptions!$C$12 -> 0.4 | D15: =C15 -> 0.4 | E15: Same reachable-segment assumption as US model.
B16: 9. Canada SAM (Serviceable Addressable Market) | C16: =C13*C15 -> 0.2428416 | D16: =D13*D15 -> 0.17727437 | E16: Row 7 x Row 8.
B18: 10. Base-case SOM as % of SAM (3–5 yr) | C18: =Assumptions!$C$13 -> 0.015 | D18: =C18 -> 0.015 | E18: Realistic new-entrant capture.
B19: 11. Canada SOM — Base case | C19: =C16*C18 -> 0.003642624 | D19: =D16*D18 -> 0.0026591155 | E19: Row 9 x Row 10.
B20: 12. Optimistic SOM as % of SAM (upside) | C20: =Assumptions!$C$14 -> 0.03 | D20: =C20 -> 0.03 | E20: Upside case.
B21: 13. Canada SOM — Upside case | C21: =C16*C20 -> 0.007285248 | D21: =D16*D20 -> 0.005318231 | E21: Row 9 x Row 12.

Sheet Canada Province Breakdown
A1: Canada — Province/Territory TAM / SAM / SOM
A2: Apportioned from the Canada National Model using population share x a directional per-capita health-spend index (higher for the territories, reflecting remote-care delivery cost). VERIFY against CIHI provincial data before external use.
B4: Province / Territory | C4: 2024E Population (M) | D4: Pop. Share | E4: Per-Capita Spend Index | F4: Weighted Share | G4: TAM (US$M) | H4: SAM (US$M) | I4: SOM — Base (US$M) | J4: SOM — Upside (US$M)
B5: Ontario | C5: 15.8 | D5: =C5/SUM($C$5:$C$17) -> 0.38963281 | E5: 0.95 | F5: =D5*E5 -> 0.37015117 | G5: =($F5/$F$19)*'Canada National Model'!$D$13*1000 -> 165.15808 | H5: =($F5/$F$19)*'Canada National Model'!$D$16*1000 -> 66.063232 | I5: =($F5/$F$19)*'Canada National Model'!$D$19*1000 -> 0.99094848 | J5: =($F5/$F$19)*'Canada National Model'!$D$21*1000 -> 1.981897
B6: Quebec | C6: 8.9 | D6: =C6/SUM($C$5:$C$17) -> 0.21947671 | E6: 1 | F6: =D6*E6 -> 0.21947671 | G6: =($F6/$F$19)*'Canada National Model'!$D$13*1000 -> 97.928509 | H6: =($F6/$F$19)*'Canada National Model'!$D$16*1000 -> 39.171404 | I6: =($F6/$F$19)*'Canada National Model'!$D$19*1000 -> 0.58757105 | J6: =($F6/$F$19)*'Canada National Model'!$D$21*1000 -> 1.1751421
B7: British Columbia | C7: 5.6 | D7: =C7/SUM($C$5:$C$17) -> 0.1380977 | E7: 1 | F7: =D7*E7 -> 0.1380977 | G7: =($F7/$F$19)*'Canada National Model'!$D$13*1000 -> 61.617938 | H7: =($F7/$F$19)*'Canada National Model'!$D$16*1000 -> 24.647175 | I7: =($F7/$F$19)*'Canada National Model'!$D$19*1000 -> 0.36970763 | J7: =($F7/$F$19)*'Canada National Model'!$D$21*1000 -> 0.73941526
B8: Alberta | C8: 4.8 | D8: =C8/SUM($C$5:$C$17) -> 0.11836946 | E8: 0.98 | F8: =D8*E8 -> 0.11600207 | G8: =($F8/$F$19)*'Canada National Model'!$D$13*1000 -> 51.759068 | H8: =($F8/$F$19)*'Canada National Model'!$D$16*1000 -> 20.703627 | I8: =($F8/$F$19)*'Canada National Model'!$D$19*1000 -> 0.31055441 | J8: =($F8/$F$19)*'Canada National Model'!$D$21*1000 -> 0.62110882
B9: Manitoba | C9: 1.5 | D9: =C9/SUM($C$5:$C$17) -> 0.036990456 | E9: 1.05 | F9: =D9*E9 -> 0.038839979 | G9: =($F9/$F$19)*'Canada National Model'!$D$13*1000 -> 17.330045 | H9: =($F9/$F$19)*'Canada National Model'!$D$16*1000 -> 6.932018 | I9: =($F9/$F$19)*'Canada National Model'!$D$19*1000 -> 0.10398027 | J9: =($F9/$F$19)*'Canada National Model'!$D$21*1000 -> 0.20796054
B10: Saskatchewan | C10: 1.2 | D10: =C10/SUM($C$5:$C$17) -> 0.029592365 | E10: 1.05 | F10: =D10*E10 -> 0.031071983 | G10: =($F10/$F$19)*'Canada National Model'!$D$13*1000 -> 13.864036 | H10: =($F10/$F$19)*'Canada National Model'!$D$16*1000 -> 5.5456144 | I10: =($F10/$F$19)*'Canada National Model'!$D$19*1000 -> 0.083184217 | J10: =($F10/$F$19)*'Canada National Model'!$D$21*1000 -> 0.16636843
B11: Nova Scotia | C11: 1.05 | D11: =C11/SUM($C$5:$C$17) -> 0.02589332 | E11: 1.1 | F11: =D11*E11 -> 0.028482651 | G11: =($F11/$F$19)*'Canada National Model'!$D$13*1000 -> 12.7087 | H11: =($F11/$F$19)*'Canada National Model'!$D$16*1000 -> 5.0834799 | I11: =($F11/$F$19)*'Canada National Model'!$D$19*1000 -> 0.076252198 | J11: =($F11/$F$19)*'Canada National Model'!$D$21*1000 -> 0.1525044
B12: New Brunswick | C12: 0.85 | D12: =C12/SUM($C$5:$C$17) -> 0.020961259 | E12: 1.08 | F12: =D12*E12 -> 0.022638159 | G12: =($F12/$F$19)*'Canada National Model'!$D$13*1000 -> 10.100941 | H12: =($F12/$F$19)*'Canada National Model'!$D$16*1000 -> 4.0403762 | I12: =($F12/$F$19)*'Canada National Model'!$D$19*1000 -> 0.060605643 | J12: =($F12/$F$19)*'Canada National Model'!$D$21*1000 -> 0.12121129
B13: Newfoundland & Labrador | C13: 0.54 | D13: =C13/SUM($C$5:$C$17) -> 0.013316564 | E13: 1.25 | F13: =D13*E13 -> 0.016645705 | G13: =($F13/$F$19)*'Canada National Model'!$D$13*1000 -> 7.4271622 | H13: =($F13/$F$19)*'Canada National Model'!$D$16*1000 -> 2.9708649 | I13: =($F13/$F$19)*'Canada National Model'!$D$19*1000 -> 0.044562973 | J13: =($F13/$F$19)*'Canada National Model'!$D$21*1000 -> 0.089125946
B14: Prince Edward Island | C14: 0.18 | D14: =C14/SUM($C$5:$C$17) -> 0.0044388548 | E14: 1.1 | F14: =D14*E14 -> 0.0048827403 | G14: =($F14/$F$19)*'Canada National Model'!$D$13*1000 -> 2.1786342 | H14: =($F14/$F$19)*'Canada National Model'!$D$16*1000 -> 0.8714537 | I14: =($F14/$F$19)*'Canada National Model'!$D$19*1000 -> 0.013071805 | J14: =($F14/$F$19)*'Canada National Model'!$D$21*1000 -> 0.026143611
B15: Northwest Territories | C15: 0.045 | D15: =C15/SUM($C$5:$C$17) -> 0.0011097137 | E15: 2.2 | F15: =D15*E15 -> 0.0024413701 | G15: =($F15/$F$19)*'Canada National Model'!$D$13*1000 -> 1.0893171 | H15: =($F15/$F$19)*'Canada National Model'!$D$16*1000 -> 0.43572685 | I15: =($F15/$F$19)*'Canada National Model'!$D$19*1000 -> 0.0065359027 | J15: =($F15/$F$19)*'Canada National Model'!$D$21*1000 -> 0.013071805
B16: Yukon | C16: 0.045 | D16: =C16/SUM($C$5:$C$17) -> 0.0011097137 | E16: 1.9 | F16: =D16*E16 -> 0.002108456 | G16: =($F16/$F$19)*'Canada National Model'!$D$13*1000 -> 0.94077388 | H16: =($F16/$F$19)*'Canada National Model'!$D$16*1000 -> 0.37630955 | I16: =($F16/$F$19)*'Canada National Model'!$D$19*1000 -> 0.0056446433 | J16: =($F16/$F$19)*'Canada National Model'!$D$21*1000 -> 0.011289287
B17: Nunavut | C17: 0.041 | D17: =C17/SUM($C$5:$C$17) -> 0.0010110725 | E17: 2.4 | F17: =D17*E17 -> 0.0024265739 | G17: =($F17/$F$19)*'Canada National Model'!$D$13*1000 -> 1.0827152 | H17: =($F17/$F$19)*'Canada National Model'!$D$16*1000 -> 0.43308608 | I17: =($F17/$F$19)*'Canada National Model'!$D$19*1000 -> 0.0064962912 | J17: =($F17/$F$19)*'Canada National Model'!$D$21*1000 -> 0.012992582
B19: TOTAL (sum of weighted shares — used to normalize) | F19: =SUM(F5:F17) -> 0.99326527
B20: CANADA TOTAL (all provinces + territories) | G20: =SUM(G5:G17) -> 443.18592 | H20: =SUM(H5:H17) -> 177.27437 | I20: =SUM(I5:I17) -> 2.6591155 | J20: =SUM(J5:J17) -> 5.318231
